Workbook

Sheet Summary
A1: Objective: | B1: Maximize farm profit through optimal crop mix across successions while keeping land, water, labor, storage, demand and budget constraints.
A2: Workflow: | B2: 1. Input crop data & constraints → 2. LP + binary optimization → 3. Planting schedules & financials → 4. Scenario testing
A3: Applications: | B3: Farm management software • Agricultural consulting • Cooperative planning • Education • Climate adaptation
A4: Limitations
A5: Rigid crop calendar (6 crops) | B5: Simplified for model-building. Real farms typically include more crops. Each succession has a hardcoded planting month (orange DV), growing months, and harvest month (purple). Adding new successions or crops requires manually building formulas throughout the sheet. Improvement: an app where farmers input crop, days to maturity, and seasonality — then successions auto-generate.
A6: No channel optimization | B6: Sales are not allocated across channels by the optimizer. See Appendix 1 (DV-based channel partitioning) or Appendix 2 (waterfall method using =SORT functions to prioritize) for more accurate approaches — both too complex for this assignment.
A7: Monthly time resolution (not 52 weeks) | B7: Days to maturity and planting/harvesting are simplified into whole months. A 52-week model would be more accurate but was not feasible for this assignment due to complexity.
A8: Fixed cost ≥ budget → infeasible | B8: Fixed costs (storage, irrigation, equipment, machinery) are set by user parameters, not DVs. If land > 462 acres, storage > 84,400 m³, or budget < $1.17M, fixed costs alone exceed the budget and Solver fails. An app must warn users before this happens.
A9: Stress-tested: 120 scenarios | B9: Model confirmed fully linear across all tests. Simplex LP is the correct and sufficient method.
A10: Core Assumptions
A11: Fixed yields, zero crop failure | B11: Yield, demand, prices, and other externally variable parameters are set values with no variance. No pest/disease loss. Monte Carlo simulation could capture risk (drought, price swings, crop failure).
A12: Strict 3–7 month crop cycles | B12: Each crop has a fixed planting → growing → harvesting timeline. No early harvest, delayed planting, or weather-adjusted schedules.
A13: 80/20 price split | B13: Revenue = yield × avg_price × 1.04 (80% sold at base price, 20% at 120% premium). This is a constant multiplier that preserves LP linearity, but if actual channel mix shifts, revenue estimates will be off.
A14: Equal sales across channels | B14: Weighted-average price and packaging costs are computed from fixed demand proportions across wholesale, D2C, and B2B. The optimizer does not allocate volume between channels.
A15: Yearly demand cap (not monthly) | B15: Monthly demand is aggregated into an annual cap, meaning buyers are not time-sensitive. Simplified due to constraint count limits.
A16: Profit-only objective | B16: Maximizes revenue minus cost. Does not consider soil health, crop rotation benefits, sustainability, or multi-year planning.
A17: Fixed infrastructure costs | B17: Storage, irrigation, equipment, and machinery costs are determined by user-set parameters (land, capacity) and are incurred regardless of what is planted. Not controlled by the optimizer.
A18: Binary planting decisions | B18: Each succession is either planted or not (0/1). This is not fully utilized right now, but is built in to control any succession specific fixed costs for future adaptations

Sheet Model
A1: Field Crops | B1: JAN | C1: FEB | D1: MAR | E1: APR | F1: MAY | G1: JUN | H1: JUL | I1: AUG | J1: SEP | K1: OCT | L1: NOV | M1: DEC | N1: Plant (Y/N) (Bin Const) | O1: Crop Diversity Constraint
A2: Spinach (seed) #1 | C2: 0.11082612 | D2: =C2 -> 0.11082612 | E2: =C2 -> 0.11082612 | N2: 1 | O2: =C2 -> 0.11082612 | P2: <= | Q2: =N2*'Fact Sheet'!$G$26/5 -> 0.16
A3: Spinach (seed) #2 | D3: 0.16 | E3: =D3 -> 0.16 | F3: =D3 -> 0.16 | N3: 1 | O3: =D3 -> 0.16 | P3: <= | Q3: =N3*'Fact Sheet'!$G$26/5 -> 0.16
A4: Spinach (seed) #3 | E4: 0 | F4: =E4 -> 0 | G4: =E4 -> 0 | N4: 0 | O4: =E4 -> 0 | P4: <= | Q4: =N4*'Fact Sheet'!$G$26/5 -> 0
A5: Spinach (seed) #4 | I5: 0.12637189 | J5: =I5 -> 0.12637189 | K5: =I5 -> 0.12637189 | N5: 1 | O5: =I5 -> 0.12637189 | P5: <= | Q5: =N5*'Fact Sheet'!$G$26/5 -> 0.16
A6: Spinach (seed) #5 | J6: 0.054965451 | K6: =J6 -> 0.054965451 | L6: =J6 -> 0.054965451 | N6: 1 | O6: =J6 -> 0.054965451 | P6: <= | Q6: =N6*'Fact Sheet'!$G$26/5 -> 0.16
A7: Cucumbers (seed) #1 | F7: 0.1 | G7: =F7 -> 0.1 | H7: =F7 -> 0.1 | N7: 1 | O7: =F7 -> 0.1 | P7: <= | Q7: =N7*'Fact Sheet'!$H$26/3 -> 0.1
A8: Cucumbers (seed) #2 | G8: 0.1 | H8: =G8 -> 0.1 | I8: =G8 -> 0.1 | N8: 1 | O8: =G8 -> 0.1 | P8: <= | Q8: =N8*'Fact Sheet'!$H$26/3 -> 0.1
A9: Cucumbers (seed) #3 | H9: 0.094893128 | I9: =H9 -> 0.094893128 | J9: =H9 -> 0.094893128 | N9: 1 | O9: =H9 -> 0.094893128 | P9: <= | Q9: =N9*'Fact Sheet'!$H$26/3 -> 0.1
A10: Sweet Corn #1 | F10: 0 | G10: =F10 -> 0 | H10: =F10 -> 0 | I10: =F10 -> 0 | N10: 0 | O10: =F10 -> 0 | P10: <= | Q10: =N10*'Fact Sheet'!$I$26/2 -> 0
A11: Sweet Corn #2 | G11: 0.094893128 | H11: =G11 -> 0.094893128 | I11: =G11 -> 0.094893128 | J11: =G11 -> 0.094893128 | N11: 1 | O11: =G11 -> 0.094893128 | P11: <= | Q11: =N11*'Fact Sheet'!$I$26/2 -> 0.15 | S11: Harvest & Seed/Sapling Storage | T11: =('Fact Sheet'!$B$9*'Fact Sheet'!$B$17)*11 -> 528000
A12: Napa Cabbage (transplant) #1 | D12: 0.094893128 | E12: =D12 -> 0.094893128 | F12: =D12 -> 0.094893128 | G12: =D12 -> 0.094893128 | N12: 1 | O12: =D12 -> 0.094893128 | P12: <= | Q12: =N12*'Fact Sheet'!$J$26/2 -> 0.25 | S12: Water Storage | T12: =('Fact Sheet'!$B$10*'Fact Sheet'!$B$18)*11 -> 330
A13: Napa Cabbage (transplant) #2 | I13: 0.11823187 | J13: =I13 -> 0.11823187 | K13: =I13 -> 0.11823187 | L13: =I13 -> 0.11823187 | N13: 1 | O13: =I13 -> 0.11823187 | P13: <= | Q13: =N13*'Fact Sheet'!$J$26/2 -> 0.25 | S13: Irrigation System | T13: =('Fact Sheet'!$B$8*'Fact Sheet'!$B$19)*11 -> 288750
A14: Hot Peppers (transplant) #1 | E14: 0.21021374 | F14: =E14 -> 0.21021374 | G14: =E14 -> 0.21021374 | H14: =E14 -> 0.21021374 | I14: =E14 -> 0.21021374 | J14: =E14 -> 0.21021374 | K14: =E14 -> 0.21021374 | N14: 1 | O14: =E14 -> 0.21021374 | P14: <= | Q14: =N14*'Fact Sheet'!$K$26 -> 0.3 | S14: Equipment & General Storage | T14: =('Fact Sheet'!$B$11*'Fact Sheet'!$B$20)*11 -> 660000
A15: Garlic (seed) #1 | B15: 0.4 | C15: =B15 -> 0.4 | D15: =B15 -> 0.4 | E15: =B15 -> 0.4 | F15: =B15 -> 0.4 | G15: =B15 -> 0.4 | H15: =B15 -> 0.4 | N15: 1 | O15: =B15 -> 0.4 | P15: <= | Q15: =N15*'Fact Sheet'!$L$26 -> 0.5 | S15: Fuel Storage | T15: =('Fact Sheet'!$B$12*'Fact Sheet'!$B$21)*11 -> 1650
A16: Available Land Constraint | B16: =SUM(B2:B15) -> 0.4 | C16: =SUM(C2:C15) -> 0.51082612 | D16: =SUM(D2:D15) -> 0.76571925 | E16: =SUM(E2:E15) -> 0.97593299 | F16: =SUM(F2:F15) -> 0.96510687 | G16: =SUM(G2:G15) -> 1 | H16: =SUM(H2:H15) -> 1 | I16: =SUM(I2:I15) -> 0.74460376 | ... M16: =SUM(M2:M15) -> 0 | S16: Machinery | T16: =('Fact Sheet'!$B$22)*11 -> 28600
B17: <= | C17: <= | D17: <= | E17: <= | F17: <= | G17: <= | H17: <= | I17: <= | J17: <= | K17: <= | L17: <= | M17: <= | S17: Total Fixed Cost (Annual) | T17: =SUM(T11:T16) -> 1507330
B18: ='Fact Sheet'!$B$8/'Fact Sheet'!$B$8 -> 1 | C18: ='Fact Sheet'!$B$8/'Fact Sheet'!$B$8 -> 1 | D18: ='Fact Sheet'!$B$8/'Fact Sheet'!$B$8 -> 1 | E18: ='Fact Sheet'!$B$8/'Fact Sheet'!$B$8 -> 1 | F18: ='Fact Sheet'!$B$8/'Fact Sheet'!$B$8 -> 1 | G18: ='Fact Sheet'!$B$8/'Fact Sheet'!$B$8 -> 1 | H18: ='Fact Sheet'!$B$8/'Fact Sheet'!$B$8 -> 1 | I18: ='Fact Sheet'!$B$8/'Fact Sheet'!$B$8 -> 1 | ... M18: ='Fact Sheet'!$B$8/'Fact Sheet'!$B$8 -> 1
B21: JAN | C21: FEB | D21: MAR | E21: APR | F21: MAY | G21: JUN | H21: JUL | I21: AUG | J21: SEP | K21: OCT | L21: NOV | M21: DEC | T21: JAN | U21: FEB | V21: MAR | W21: APR | X21: MAY | Y21: JUN | Z21: JUL | AA21: AUG | AB21: SEP | AC21: OCT | AD21: NOV | AE21: DEC
A22: Spinach | B22: 0 | C22: 0 | D22: 0 | E22: =$E$2*'Fact Sheet'!$B$8*'Fact Sheet'!$G$9 -> 216110.93 | F22: =$F$3*'Fact Sheet'!$B$8*'Fact Sheet'!$G$9 -> 312000 | G22: =$G$4*'Fact Sheet'!$B$8*'Fact Sheet'!$G$9 -> 0 | H22: 0 | I22: 0 | J22: 0 | K22: =$K$5*'Fact Sheet'!$B$8*'Fact Sheet'!$G$9 -> 246425.19 | L22: =$L$6*'Fact Sheet'!$B$8*'Fact Sheet'!$G$9 -> 107182.63 | M22: 0 | N22: =SUM(B22:M22) -> 881718.75 | O22: <= | P22: ='Fact Sheet'!$G$34*11 -> 881718.75 | S22: Spinach | T22: 0 | U22: 0 | V22: 0 | W22: =($E$22*0.8*'Fact Sheet'!$G$39)+($E$22*0.2*'Fact Sheet'!$G$39*1.2) -> 778757.63 | X22: =($F$22*0.8*'Fact Sheet'!$G$39)+($F$22*0.2*'Fact Sheet'!$G$39*1.2) -> 1124294.7 | Y22: =($G$22*0.8*'Fact Sheet'!$G$39)+($G$22*0.2*'Fact Sheet'!$G$39*1.2) -> 0 | Z22: 0 | AA22: 0 | AB22: 0 | AC22: =($K$22*0.8*'Fact Sheet'!$G$39)+($K$22*0.2*'Fact Sheet'!$G$39*1.2) -> 887995.33 | AD22: =($L$22*0.8*'Fact Sheet'!$G$39)+($L$22*0.2*'Fact Sheet'!$G$39*1.2) -> 386233.55 | AE22: 0 | AF22: =SUM(T22:AE22) -> 3177281.2
A23: Cucumbers | B23: 0 | C23: 0 | D23: 0 | E23: 0 | F23: 0 | G23: 0 | H23: =$H$7*'Fact Sheet'!$B$8*'Fact Sheet'!$H$9 -> 240000 | I23: =$I$8*'Fact Sheet'!$B$8*'Fact Sheet'!$H$9 -> 240000 | J23: =$J$9*'Fact Sheet'!$B$8*'Fact Sheet'!$H$9 -> 227743.51 | K23: 0 | L23: 0 | M23: 0 | N23: =SUM(B23:M23) -> 707743.51 | O23: <= | P23: ='Fact Sheet'!$H$34*11 -> 897187.5 | S23: Cucumbers | T23: 0 | U23: 0 | V23: 0 | W23: 0 | X23: 0 | Y23: 0 | Z23: =($H$23*0.8*'Fact Sheet'!$H$39)+($H$23*0.2*'Fact Sheet'!$H$39*1.2) -> 406675.86 | AA23: =($I$23*0.8*'Fact Sheet'!$H$39)+($I$23*0.2*'Fact Sheet'!$H$39*1.2) -> 406675.86 | AB23: =($J$23*0.8*'Fact Sheet'!$H$39)+($J$23*0.2*'Fact Sheet'!$H$39*1.2) -> 385907.45 | AC23: 0 | AD23: 0 | AE23: 0 | AF23: =SUM(T23:AE23) -> 1199259.2
A24: Sweet Corn | B24: 0 | C24: 0 | D24: 0 | E24: 0 | F24: 0 | G24: 0 | H24: 0 | I24: =$I$10*'Fact Sheet'!$B$8*'Fact Sheet'!$I$9 -> 0 | J24: =$J$11*'Fact Sheet'!$B$8*'Fact Sheet'!$I$9 -> 142339.69 | K24: 0 | L24: 0 | M24: 0 | N24: =SUM(B24:M24) -> 142339.69 | O24: <= | P24: ='Fact Sheet'!$I$34*11 -> 550000 | S24: Sweet Corn | T24: 0 | U24: 0 | V24: 0 | W24: 0 | X24: 0 | Y24: 0 | Z24: 0 | AA24: =($I$24*0.8*'Fact Sheet'!$I$39)+($I$24*0.2*'Fact Sheet'!$I$39*1.2) -> 0 | AB24: =($J$24*0.8*'Fact Sheet'!$I$39)+($J$24*0.2*'Fact Sheet'!$I$39*1.2) -> 336775.71 | AC24: 0 | AD24: 0 | AE24: 0 | AF24: =SUM(T24:AE24) -> 336775.71
A25: Napa Cabbage | B25: 0 | C25: 0 | D25: 0 | E25: 0 | F25: 0 | G25: =$G$12*'Fact Sheet'!$B$8*'Fact Sheet'!$J$9 -> 640528.61 | H25: 0 | I25: 0 | J25: 0 | K25: 0 | L25: =$L$13*'Fact Sheet'!$B$8*'Fact Sheet'!$J$9 -> 798065.14 | M25: 0 | N25: =SUM(B25:M25) -> 1438593.8 | O25: <= | P25: ='Fact Sheet'!$J$34*11 -> 1438593.8 | S25: Napa Cabbage | T25: 0 | U25: 0 | V25: 0 | W25: 0 | X25: 0 | Y25: =($G$25*0.8*'Fact Sheet'!$J$39)+($G$25*0.2*'Fact Sheet'!$J$39*1.2) -> 485286.52 | Z25: 0 | AA25: 0 | AB25: 0 | AC25: 0 | AD25: =($L$25*0.8*'Fact Sheet'!$J$39)+($L$25*0.2*'Fact Sheet'!$J$39*1.2) -> 604641.61 | AE25: 0 | AF25: =SUM(T25:AE25) -> 1089928.1
A26: Hot Peppers | B26: 0 | C26: 0 | D26: 0 | E26: 0 | F26: 0 | G26: 0 | H26: 0 | I26: =$I$14*'Fact Sheet'!$B$8*'Fact Sheet'!$K$9 -> 157660.31 | J26: =$J$14*'Fact Sheet'!$B$8*'Fact Sheet'!$K$9 -> 157660.31 | K26: =$K$14*'Fact Sheet'!$B$8*'Fact Sheet'!$K$9 -> 157660.31 | L26: 0 | M26: 0 | N26: =SUM(B26:M26) -> 472980.93 | O26: <= | P26: ='Fact Sheet'!$K$34*11 -> 634218.75 | S26: Hot Peppers | T26: 0 | U26: 0 | V26: 0 | W26: 0 | X26: 0 | Y26: 0 | Z26: 0 | AA26: =($I$26*0.8*'Fact Sheet'!$K$39)+($I$26*0.2*'Fact Sheet'!$K$39*1.2) -> 435911.53 | AB26: =($J$26*0.8*'Fact Sheet'!$K$39)+($J$26*0.2*'Fact Sheet'!$K$39*1.2) -> 435911.53 | AC26: =($K$26*0.8*'Fact Sheet'!$K$39)+($K$26*0.2*'Fact Sheet'!$K$39*1.2) -> 435911.53 | AD26: 0 | AE26: 0 | AF26: =SUM(T26:AE26) -> 1307734.6
A27: Garlic | B27: 0 | C27: 0 | D27: 0 | E27: 0 | F27: 0 | G27: 0 | H27: =$H$15*'Fact Sheet'!$B$8*'Fact Sheet'!$L$9 -> 660000 | I27: 0 | J27: 0 | K27: 0 | L27: 0 | M27: 0 | N27: =SUM(B27:M27) -> 660000 | O27: <= | P27: ='Fact Sheet'!$L$34*11 -> 1132312.5 | S27: Garlic | T27: 0 | U27: 0 | V27: 0 | W27: 0 | X27: 0 | Y27: 0 | Z27: =($H$27*0.8*'Fact Sheet'!$L$39)+($H$27*0.2*'Fact Sheet'!$L$39*1.2) -> 1969180.3 | AA27: 0 | AB27: 0 | AC27: 0 | AD27: 0 | AE27: 0 | AF27: =SUM(T27:AE27) -> 1969180.3
A28: Yield vs Demand Constraint | S28: Total Revenue | T28: =SUM(T22:T27) -> 0 | U28: =SUM(U22:U27) -> 0 | V28: =SUM(V22:V27) -> 0 | W28: =SUM(W22:W27) -> 778757.63 | X28: =SUM(X22:X27) -> 1124294.7 | Y28: =SUM(Y22:Y27) -> 485286.52 | Z28: =SUM(Z22:Z27) -> 2375856.2 | AA28: =SUM(AA22:AA27) -> 842587.39 | ... AE28: =SUM(AE22:AE27) -> 0 | AF28: =SUM(T28:AE28) -> 9080159.2
A32: Spinach | B32: 0 | C32: =$C$2*'Fact Sheet'!$B$8*'Fact Sheet'!$G$45 -> 249.35877 | D32: =($D$3*'Fact Sheet'!$B$8*'Fact Sheet'!$G$45)+($D$2*'Fact Sheet'!$B$8*'Fact Sheet'!$G$46) -> 559.48701 | E32: =($E$4*'Fact Sheet'!$B$8*'Fact Sheet'!$G$45)+($E$3*'Fact Sheet'!$B$8*'Fact Sheet'!$G$46)+($E$2*'Fact Sheet'!$B$8*'Fact Sheet'!$G$47) -> 1950.3918 | F32: =($F$4*'Fact Sheet'!$B$8*'Fact Sheet'!$G$46)+($F$3*'Fact Sheet'!$B$8*'Fact Sheet'!$G$47) -> 2400 | G32: =$G$4*'Fact Sheet'!$B$8*'Fact Sheet'!$G$47 -> 0 | H32: 0 | I32: =$I$5*'Fact Sheet'!$B$8*'Fact Sheet'!$G$45 -> 284.33676 | J32: =($J$6*'Fact Sheet'!$B$8*'Fact Sheet'!$G$45)+($J$5*'Fact Sheet'!$B$8*'Fact Sheet'!$G$46) -> 351.14167 | K32: =($K$6*'Fact Sheet'!$B$8*'Fact Sheet'!$G$46)+($K$5*'Fact Sheet'!$B$8*'Fact Sheet'!$G$47) -> 1994.5162 | L32: =$L$6*'Fact Sheet'!$B$8*'Fact Sheet'!$G$47 -> 824.48177 | M32: 0 | N32: =SUM(B32:M32) -> 8613.7139 | S32: Seed | T32: =$B$15*'Fact Sheet'!$B$8*'Fact Sheet'!$L$8*'Fact Sheet'!$L$43 -> 300000 | U32: =$C$2*'Fact Sheet'!$B$8*'Fact Sheet'!$G$8*'Fact Sheet'!$G$43 -> 3324.7835 | V32: =($D$3*'Fact Sheet'!$B$8*'Fact Sheet'!$G$8*'Fact Sheet'!$G$43)+($D$12*'Fact Sheet'!$B$8*'Fact Sheet'!$J$8*'Fact Sheet'!$J$43) -> 5440.5286 | W32: =($E$4*'Fact Sheet'!$B$8*'Fact Sheet'!$G$8*'Fact Sheet'!$G$43)+($E$14*'Fact Sheet'!$B$8*'Fact Sheet'!$K$8*'Fact Sheet'!$K$43) -> 1324.3466 | X32: =($F$7*'Fact Sheet'!$B$8*'Fact Sheet'!$H$8*'Fact Sheet'!$H$43)+($F$10*'Fact Sheet'!$B$8*'Fact Sheet'!$I$8*'Fact Sheet'!$I$43) -> 1687.5 | Y32: =($G$8*'Fact Sheet'!$B$8*'Fact Sheet'!$H$8*'Fact Sheet'!$H$43)+($G$11*'Fact Sheet'!$B$8*'Fact Sheet'!$I$8*'Fact Sheet'!$I$43) -> 2541.5381 | Z32: =$H$9*'Fact Sheet'!$B$8*'Fact Sheet'!$H$8*'Fact Sheet'!$H$43 -> 1601.3215 | AA32: =($I$5*'Fact Sheet'!$B$8*'Fact Sheet'!$G$8*'Fact Sheet'!$G$43)+($I$13*'Fact Sheet'!$B$8*'Fact Sheet'!$J$8*'Fact Sheet'!$J$43) -> 4589.2219 | AB32: =$J$6*'Fact Sheet'!$B$8*'Fact Sheet'!$G$8*'Fact Sheet'!$G$43 -> 1648.9635 | AC32: 0 | AD32: 0 | AE32: 0 | AF32: =SUM(T32:AE32) -> 322158.2
A33: Cucumbers | B33: 0 | C33: 0 | D33: 0 | E33: 0 | F33: =$F$7*'Fact Sheet'!$B$8*'Fact Sheet'!$H$45 -> 225 | G33: =($G$8*'Fact Sheet'!$B$8*'Fact Sheet'!$H$45)+($G$7*'Fact Sheet'!$B$8*'Fact Sheet'!$H$46) -> 405 | H33: =($H$9*'Fact Sheet'!$B$8*'Fact Sheet'!$H$45)+($H$8*'Fact Sheet'!$B$8*'Fact Sheet'!$H$46)+($H$7*'Fact Sheet'!$B$8*'Fact Sheet'!$H$47) -> 2343.5095 | I33: =($I$9*'Fact Sheet'!$B$8*'Fact Sheet'!$H$46)+($I$8*'Fact Sheet'!$B$8*'Fact Sheet'!$H$47) -> 2120.8076 | J33: =$J$9*'Fact Sheet'!$B$8*'Fact Sheet'!$H$47 -> 1850.416 | K33: 0 | L33: 0 | M33: 0 | N33: =SUM(B33:M33) -> 6944.7332 | S33: Water Supply | T33: =B48*'Fact Sheet'!$B$29 -> 180 | U33: =C48*'Fact Sheet'!$B$29 -> 101.55979 | V33: =D48*'Fact Sheet'!$B$29 -> 210.18371 | W33: =E48*'Fact Sheet'!$B$29 -> 300 | X33: =F48*'Fact Sheet'!$B$29 -> 273.79809 | Y33: =G48*'Fact Sheet'!$B$29 -> 262.88302 | Z33: =H48*'Fact Sheet'!$B$29 -> 300 | AA33: =I48*'Fact Sheet'!$B$29 -> 208.7116 | ... AD33: =L48*'Fact Sheet'!$B$29 -> 62.887792 | AE33: 0 | AF33: =SUM(T33:AE33) -> 2213.7174
A34: Sweet Corn | B34: 0 | C34: 0 | D34: 0 | E34: 0 | F34: =$F$10*'Fact Sheet'!$B$8*'Fact Sheet'!$I$45 -> 0 | G34: =($G$11*'Fact Sheet'!$B$8*'Fact Sheet'!$I$45)+($G$10*'Fact Sheet'!$B$8*'Fact Sheet'!$I$46) -> 142.33969 | H34: =($H$11*'Fact Sheet'!$B$8*'Fact Sheet'!$I$46)+($H$10*'Fact Sheet'!$B$8*'Fact Sheet'!$I$46) -> 85.403815 | I34: =($I$11*'Fact Sheet'!$B$8*'Fact Sheet'!$I$46)+($I$10*'Fact Sheet'!$B$8*'Fact Sheet'!$I$47) -> 85.403815 | J34: =$J$11*'Fact Sheet'!$B$8*'Fact Sheet'!$I$47 -> 2846.7938 | K34: 0 | L34: 0 | M34: 0 | N34: =SUM(B34:M34) -> 3159.9412 | S34: Fertilizer & Pesticide | T34: =$B$15*'Fact Sheet'!$B$8*'Fact Sheet'!$L$22*'Fact Sheet'!$B$26 -> 960 | U34: =($C$2*'Fact Sheet'!$B$8*'Fact Sheet'!$G$22*'Fact Sheet'!$B$26)+($C$15*'Fact Sheet'!$B$8*'Fact Sheet'!$L$23*'Fact Sheet'!$B$26) -> 1098.7175 | V34: =($D$2*'Fact Sheet'!$B$8*'Fact Sheet'!$G$23*'Fact Sheet'!$B$26)+($D$3*'Fact Sheet'!$B$8*'Fact Sheet'!$G$22*'Fact Sheet'!$B$26)+($D$12*'Fact Sheet'!$B$8*'Fact Sheet'!$J$22*'Fact Sheet'!$B$26)+($D$15*'Fact Sheet'!$B$8*'Fact Sheet'!$L$23*'Fact Sheet'!$B$26) -> 2079.4974 | W34: =($E$2*'Fact Sheet'!$B$8*'Fact Sheet'!$G$24*'Fact Sheet'!$B$26)+($E$3*'Fact Sheet'!$B$8*'Fact Sheet'!$G$23*'Fact Sheet'!$B$26)+($E$4*'Fact Sheet'!$B$8*'Fact Sheet'!$G$22*'Fact Sheet'!$B$26)+($E$12*'Fact Sheet'!$B$8*'Fact Sheet'!$J$23*'Fact Sheet'!$B$26)+($E$14*'Fact Sheet'!$B$8*'Fact Sheet'!$K$22*'Fact Sheet'!$B$26)+($E$15*'Fact Sheet'!$B$8*'Fact Sheet'!$L$23*'Fact Sheet'!$B$26) -> 2161.5598 | X34: =($F$3*'Fact Sheet'!$B$8*'Fact Sheet'!$G$24*'Fact Sheet'!$B$26)+($F$4*'Fact Sheet'!$B$8*'Fact Sheet'!$G$23*'Fact Sheet'!$B$26)+($F$7*'Fact Sheet'!$B$8*'Fact Sheet'!$H$22*'Fact Sheet'!$B$26)+($F$10*'Fact Sheet'!$B$8*'Fact Sheet'!$I$22*'Fact Sheet'!$B$26)+($F$12*'Fact Sheet'!$B$8*'Fact Sheet'!$J$23*'Fact Sheet'!$B$26)+($F$14*'Fact Sheet'!$B$8*'Fact Sheet'!$K$23*'Fact Sheet'!$B$26)+($F$15*'Fact Sheet'!$B$8*'Fact Sheet'!$L$23*'Fact Sheet'!$B$26) -> 2241.4489 | Y34: =($G$4*'Fact Sheet'!$B$8*'Fact Sheet'!$G$24*'Fact Sheet'!$B$26)+($G$7*'Fact Sheet'!$B$8*'Fact Sheet'!$H$23*'Fact Sheet'!$B$26)+($G$8*'Fact Sheet'!$B$8*'Fact Sheet'!$H$22*'Fact Sheet'!$B$26)+($G$10*'Fact Sheet'!$B$8*'Fact Sheet'!$I$23*'Fact Sheet'!$B$26)+($G$11*'Fact Sheet'!$B$8*'Fact Sheet'!$I$22*'Fact Sheet'!$B$26)+($G$12*'Fact Sheet'!$B$8*'Fact Sheet'!$J$24*'Fact Sheet'!$B$26)+($G$14*'Fact Sheet'!$B$8*'Fact Sheet'!$K$23*'Fact Sheet'!$B$26)+($G$15*'Fact Sheet'!$B$8*'Fact Sheet'!$L$23*'Fact Sheet'!$B$26) -> 2668.4679 | Z34: =($H$7*'Fact Sheet'!$B$8*'Fact Sheet'!$H$24*'Fact Sheet'!$B$26)+($H$8*'Fact Sheet'!$B$8*'Fact Sheet'!$H$23*'Fact Sheet'!$B$26)+($H$9*'Fact Sheet'!$B$8*'Fact Sheet'!$H$22*'Fact Sheet'!$B$26)+($H$10*'Fact Sheet'!$B$8*'Fact Sheet'!$I$23*'Fact Sheet'!$B$26)+($H$11*'Fact Sheet'!$B$8*'Fact Sheet'!$I$23*'Fact Sheet'!$B$26)+($H$14*'Fact Sheet'!$B$8*'Fact Sheet'!$K$23*'Fact Sheet'!$B$26)+($H$15*'Fact Sheet'!$B$8*'Fact Sheet'!$L$24*'Fact Sheet'!$B$26) -> 2275.4038 | AA34: =($I$5*'Fact Sheet'!$B$8*'Fact Sheet'!$G$22*'Fact Sheet'!$B$26)+($I$8*'Fact Sheet'!$B$8*'Fact Sheet'!$H$24*'Fact Sheet'!$B$26)+($I$9*'Fact Sheet'!$B$8*'Fact Sheet'!$H$23*'Fact Sheet'!$B$26)+($I$10*'Fact Sheet'!$B$8*'Fact Sheet'!$I$24*'Fact Sheet'!$B$26)+($I$11*'Fact Sheet'!$B$8*'Fact Sheet'!$I$23*'Fact Sheet'!$B$26)+($I$13*'Fact Sheet'!$B$8*'Fact Sheet'!$J$22*'Fact Sheet'!$B$26)+($I$14*'Fact Sheet'!$B$8*'Fact Sheet'!$K$24*'Fact Sheet'!$B$26) -> 2283.8643 | AB34: =($J$5*'Fact Sheet'!$B$8*'Fact Sheet'!$G$23*'Fact Sheet'!$B$26)+($J$6*'Fact Sheet'!$B$8*'Fact Sheet'!$G$22*'Fact Sheet'!$B$26)+($J$9*'Fact Sheet'!$B$8*'Fact Sheet'!$H$24*'Fact Sheet'!$B$26)+($J$11*'Fact Sheet'!$B$8*'Fact Sheet'!$I$24*'Fact Sheet'!$B$26)+($J$13*'Fact Sheet'!$B$8*'Fact Sheet'!$J$23*'Fact Sheet'!$B$26)+($J$14*'Fact Sheet'!$B$8*'Fact Sheet'!$K$24*'Fact Sheet'!$B$26) -> 1729.6238 | AC34: =($K$5*'Fact Sheet'!$B$8*'Fact Sheet'!$G$24*'Fact Sheet'!$B$26)+($K$6*'Fact Sheet'!$B$8*'Fact Sheet'!$G$23*'Fact Sheet'!$B$26)+($K$13*'Fact Sheet'!$B$8*'Fact Sheet'!$J$23*'Fact Sheet'!$B$26)+($K$14*'Fact Sheet'!$B$8*'Fact Sheet'!$K$24*'Fact Sheet'!$B$26) -> 1087.5345 | AD34: =($L$6*'Fact Sheet'!$B$8*'Fact Sheet'!$G$24*'Fact Sheet'!$B$26)+($L$13*'Fact Sheet'!$B$8*'Fact Sheet'!$J$24*'Fact Sheet'!$B$26) -> 259.79599 | AE34: 0 | AF34: =SUM(T34:AE34) -> 18845.914
A35: Napa Cabbage | B35: 0 | C35: 0 | D35: =$D$12*'Fact Sheet'!$B$8*'Fact Sheet'!$J$45 -> 142.33969 | E35: =$E$12*'Fact Sheet'!$B$8*'Fact Sheet'!$J$46 -> 85.403815 | F35: =$F$12*'Fact Sheet'!$B$8*'Fact Sheet'!$J$46 -> 85.403815 | G35: =$G$12*'Fact Sheet'!$B$8*'Fact Sheet'!$J$47 -> 1138.7175 | H35: 0 | I35: =$I$13*'Fact Sheet'!$B$8*'Fact Sheet'!$J$45 -> 177.34781 | J35: =$J$13*'Fact Sheet'!$B$8*'Fact Sheet'!$J$46 -> 106.40869 | K35: =$K$13*'Fact Sheet'!$B$8*'Fact Sheet'!$J$46 -> 106.40869 | L35: =$L$13*'Fact Sheet'!$B$8*'Fact Sheet'!$J$47 -> 1418.7825 | M35: 0 | N35: =SUM(B35:M35) -> 3260.8125 | S35: Packaging | T35: 0 | U35: 0 | V35: 0 | W35: =E22*'Fact Sheet'!$G$58 -> 13857.64 | X35: =F22*'Fact Sheet'!$G$58 -> 20006.316 | Y35: =(G22*'Fact Sheet'!$G$58)+(G25*'Fact Sheet'!$J$58) -> 34023.778 | Z35: =(H23*'Fact Sheet'!$H$58)+(H27*'Fact Sheet'!$L$58) -> 35672.357 | AA35: =(I23*'Fact Sheet'!$H$58)+(I24*'Fact Sheet'!$I$58)+(I26*'Fact Sheet'!$K$58) -> 19424.508 | AB35: =(J23*'Fact Sheet'!$H$58)+(J24*'Fact Sheet'!$I$58)+(J26*'Fact Sheet'!$K$58) -> 25454.402 | AC35: =(K22*'Fact Sheet'!$G$58)+(K26*'Fact Sheet'!$K$58) -> 25088.052 | AD35: =(L22*'Fact Sheet'!$G$58)+(L25*'Fact Sheet'!$J$58) -> 49264.698 | AE35: 0 | AF35: =SUM(T35:AE35) -> 222791.75
A36: Hot Peppers | B36: 0 | C36: 0 | D36: 0 | E36: =$E$14*'Fact Sheet'!$B$8*'Fact Sheet'!$K$45 -> 630.64123 | F36: =$F$14*'Fact Sheet'!$B$8*'Fact Sheet'!$K$46 -> 472.98093 | G36: =$G$14*'Fact Sheet'!$B$8*'Fact Sheet'!$K$46 -> 472.98093 | H36: =$H$14*'Fact Sheet'!$B$8*'Fact Sheet'!$K$46 -> 472.98093 | I36: =$I$14*'Fact Sheet'!$B$8*'Fact Sheet'!$K$47 -> 2522.5649 | J36: =$J$14*'Fact Sheet'!$B$8*'Fact Sheet'!$K$47 -> 2522.5649 | K36: =$K$14*'Fact Sheet'!$B$8*'Fact Sheet'!$K$47 -> 2522.5649 | L36: 0 | M36: 0 | N36: =SUM(B36:M36) -> 9617.2788 | S36: Fuel | T36: =$B$15*'Fact Sheet'!$B$8*'Fact Sheet'!$L$50*'Fact Sheet'!$B$28 -> 600 | U36: =($C$2*'Fact Sheet'!$B$8*'Fact Sheet'!$G$50*'Fact Sheet'!$B$28)+($C$15*'Fact Sheet'!$B$8*'Fact Sheet'!$L$51*'Fact Sheet'!$B$28) -> 252.99134 | V36: =($D$2*'Fact Sheet'!$B$8*'Fact Sheet'!$G$51*'Fact Sheet'!$B$28)+($D$3*'Fact Sheet'!$B$8*'Fact Sheet'!$G$50*'Fact Sheet'!$B$28)+($D$12*'Fact Sheet'!$B$8*'Fact Sheet'!$J$50*'Fact Sheet'!$B$28)+($D$15*'Fact Sheet'!$B$8*'Fact Sheet'!$L$51*'Fact Sheet'!$B$28) -> 475.74351 | W36: =($E$2*'Fact Sheet'!$B$8*'Fact Sheet'!$G$52*'Fact Sheet'!$B$28)+($E$3*'Fact Sheet'!$B$8*'Fact Sheet'!$G$51*'Fact Sheet'!$B$28)+($E$4*'Fact Sheet'!$B$8*'Fact Sheet'!$G$50*'Fact Sheet'!$B$28)+($E$12*'Fact Sheet'!$B$8*'Fact Sheet'!$J$51*'Fact Sheet'!$B$28)+($E$14*'Fact Sheet'!$B$8*'Fact Sheet'!$K$50*'Fact Sheet'!$B$28)+($E$15*'Fact Sheet'!$B$8*'Fact Sheet'!$L$51*'Fact Sheet'!$B$28) -> 555.16985 | X36: =($F$3*'Fact Sheet'!$B$8*'Fact Sheet'!$G$52*'Fact Sheet'!$B$28)+($F$4*'Fact Sheet'!$B$8*'Fact Sheet'!$G$51*'Fact Sheet'!$B$28)+($F$7*'Fact Sheet'!$B$8*'Fact Sheet'!$H$50*'Fact Sheet'!$B$28)+($F$10*'Fact Sheet'!$B$8*'Fact Sheet'!$I$50*'Fact Sheet'!$B$28)+($F$12*'Fact Sheet'!$B$8*'Fact Sheet'!$J$51*'Fact Sheet'!$B$28)+($F$14*'Fact Sheet'!$B$8*'Fact Sheet'!$K$51*'Fact Sheet'!$B$28)+($F$15*'Fact Sheet'!$B$8*'Fact Sheet'!$L$51*'Fact Sheet'!$B$28) -> 521.29809 | Y36: =($G$4*'Fact Sheet'!$B$8*'Fact Sheet'!$G$52*'Fact Sheet'!$B$28)+($G$7*'Fact Sheet'!$B$8*'Fact Sheet'!$H$51*'Fact Sheet'!$B$28)+($G$8*'Fact Sheet'!$B$8*'Fact Sheet'!$H$50*'Fact Sheet'!$B$28)+($G$10*'Fact Sheet'!$B$8*'Fact Sheet'!$I$51*'Fact Sheet'!$B$28)+($G$11*'Fact Sheet'!$B$8*'Fact Sheet'!$I$50*'Fact Sheet'!$B$28)+($G$12*'Fact Sheet'!$B$8*'Fact Sheet'!$J$52*'Fact Sheet'!$B$28)+($G$14*'Fact Sheet'!$B$8*'Fact Sheet'!$K$51*'Fact Sheet'!$B$28)+($G$15*'Fact Sheet'!$B$8*'Fact Sheet'!$L$51*'Fact Sheet'!$B$28) -> 578.10572 | Z36: =($H$7*'Fact Sheet'!$B$8*'Fact Sheet'!$H$52*'Fact Sheet'!$B$28)+($H$8*'Fact Sheet'!$B$8*'Fact Sheet'!$H$51*'Fact Sheet'!$B$28)+($H$9*'Fact Sheet'!$B$8*'Fact Sheet'!$H$50*'Fact Sheet'!$B$28)+($H$10*'Fact Sheet'!$B$8*'Fact Sheet'!$I$51*'Fact Sheet'!$B$28)+($H$11*'Fact Sheet'!$B$8*'Fact Sheet'!$I$51*'Fact Sheet'!$B$28)+($H$14*'Fact Sheet'!$B$8*'Fact Sheet'!$K$51*'Fact Sheet'!$B$28)+($H$15*'Fact Sheet'!$B$8*'Fact Sheet'!$L$52*'Fact Sheet'!$B$28) -> 670.40381 | AA36: =($I$5*'Fact Sheet'!$B$8*'Fact Sheet'!$G$50*'Fact Sheet'!$B$28)+($I$8*'Fact Sheet'!$B$8*'Fact Sheet'!$H$52*'Fact Sheet'!$B$28)+($I$9*'Fact Sheet'!$B$8*'Fact Sheet'!$H$51*'Fact Sheet'!$B$28)+($I$10*'Fact Sheet'!$B$8*'Fact Sheet'!$I$52*'Fact Sheet'!$B$28)+($I$11*'Fact Sheet'!$B$8*'Fact Sheet'!$I$51*'Fact Sheet'!$B$28)+($I$13*'Fact Sheet'!$B$8*'Fact Sheet'!$J$50*'Fact Sheet'!$B$28)+($I$14*'Fact Sheet'!$B$8*'Fact Sheet'!$K$52*'Fact Sheet'!$B$28) -> 580.05658 | AB36: =($J$5*'Fact Sheet'!$B$8*'Fact Sheet'!$G$51*'Fact Sheet'!$B$28)+($J$6*'Fact Sheet'!$B$8*'Fact Sheet'!$G$50*'Fact Sheet'!$B$28)+($J$9*'Fact Sheet'!$B$8*'Fact Sheet'!$H$52*'Fact Sheet'!$B$28)+($J$11*'Fact Sheet'!$B$8*'Fact Sheet'!$I$52*'Fact Sheet'!$B$28)+($J$13*'Fact Sheet'!$B$8*'Fact Sheet'!$J$51*'Fact Sheet'!$B$28)+($J$14*'Fact Sheet'!$B$8*'Fact Sheet'!$K$52*'Fact Sheet'!$B$28) -> 487.20008 | AC36: =($K$5*'Fact Sheet'!$B$8*'Fact Sheet'!$G$52*'Fact Sheet'!$B$28)+($K$6*'Fact Sheet'!$B$8*'Fact Sheet'!$G$51*'Fact Sheet'!$B$28)+($K$13*'Fact Sheet'!$B$8*'Fact Sheet'!$J$51*'Fact Sheet'!$B$28)+($K$14*'Fact Sheet'!$B$8*'Fact Sheet'!$K$52*'Fact Sheet'!$B$28) -> 317.80175 | AD36: =($L$6*'Fact Sheet'!$B$8*'Fact Sheet'!$G$52*'Fact Sheet'!$B$28)+($L$13*'Fact Sheet'!$B$8*'Fact Sheet'!$J$52*'Fact Sheet'!$B$28) -> 138.14281 | AE36: 0 | AF36: =SUM(T36:AE36) -> 5176.9135
A37: Garlic | B37: =$B$15*'Fact Sheet'!$B$8*'Fact Sheet'!$L$45 -> 1200 | C37: =$C$15*'Fact Sheet'!$B$8*'Fact Sheet'!$L$46 -> 480 | D37: =$D$15*'Fact Sheet'!$B$8*'Fact Sheet'!$L$46 -> 480 | E37: =$E$15*'Fact Sheet'!$B$8*'Fact Sheet'!$L$46 -> 480 | F37: =$F$15*'Fact Sheet'!$B$8*'Fact Sheet'!$L$46 -> 480 | G37: =$G$15*'Fact Sheet'!$B$8*'Fact Sheet'!$L$46 -> 480 | H37: =$H$15*'Fact Sheet'!$B$8*'Fact Sheet'!$L$47 -> 4500 | I37: 0 | J37: 0 | K37: 0 | L37: 0 | M37: 0 | N37: =SUM(B37:M37) -> 8100 | S37: Seasonal Labor | T37: =B38*'Fact Sheet'!$B$27 -> 24000 | U37: =C38*'Fact Sheet'!$B$27 -> 14587.175 | V37: =D38*'Fact Sheet'!$B$27 -> 23636.534 | W37: =E38*'Fact Sheet'!$B$27 -> 62928.736 | X37: =F38*'Fact Sheet'!$B$27 -> 73267.695 | Y37: =G38*'Fact Sheet'!$B$27 -> 52780.763 | Z37: =H38*'Fact Sheet'!$B$27 -> 148037.89 | AA37: =I38*'Fact Sheet'!$B$27 -> 103809.22 | ... AD37: =L38*'Fact Sheet'!$B$27 -> 44865.285 | AE37: 0 | AF37: =SUM(T37:AE37) -> 793929.59
A38: Seasonal Labor Constraint | B38: =SUM(B32:B37) -> 1200 | C38: =SUM(C32:C37) -> 729.35877 | D38: =SUM(D32:D37) -> 1181.8267 | E38: =SUM(E32:E37) -> 3146.4368 | F38: =SUM(F32:F37) -> 3663.3847 | G38: =SUM(G32:G37) -> 2639.0381 | H38: =SUM(H32:H37) -> 7401.8943 | I38: =SUM(I32:I37) -> 5190.4609 | ... M38: =SUM(M32:M37) -> 0 | N38: =SUM(B38:M38) -> 39696.48 | S38: Total Variable Cost | T38: =SUM(T32:T37) -> 325740 | U38: =SUM(U32:U37) -> 19365.228 | V38: =SUM(V32:V37) -> 31842.487 | W38: =SUM(W32:W37) -> 81127.452 | X38: =SUM(X32:X37) -> 97998.056 | Y38: =SUM(Y32:Y37) -> 92855.536 | Z38: =SUM(Z32:Z37) -> 188557.37 | AA38: =SUM(AA32:AA37) -> 130895.58 | ... AE38: =SUM(AE32:AE37) -> 0 | AF38: =SUM(T38:AE38) -> 1365116.1
B39: <= | C39: <= | D39: <= | E39: <= | F39: <= | G39: <= | H39: <= | I39: <= | J39: <= | K39: <= | L39: <= | M39: <=
B40: ='Fact Sheet'!$B$4 -> 1280 | C40: ='Fact Sheet'!$C$4 -> 1280 | D40: ='Fact Sheet'!$D$4 -> 1280 | E40: ='Fact Sheet'!$E$4 -> 3840 | F40: ='Fact Sheet'!$F$4 -> 3840 | G40: ='Fact Sheet'!$G$4 -> 3840 | H40: ='Fact Sheet'!$H$4 -> 7680 | I40: ='Fact Sheet'!$I$4 -> 7680 | J40: ='Fact Sheet'!$J$4 -> 7680 | K40: ='Fact Sheet'!$K$4 -> 7680 | L40: ='Fact Sheet'!$L$4 -> 3840 | M40: ='Fact Sheet'!$M$4 -> 1280
A42: Spinach | B42: 0 | C42: =$C$2*'Fact Sheet'!$B$8*'Fact Sheet'!$G$17 -> 20779.897 | D42: =($D$3*'Fact Sheet'!$B$8*'Fact Sheet'!$G$17)+($D$2*'Fact Sheet'!$B$8*'Fact Sheet'!$G$18) -> 46623.918 | E42: =($E$4*'Fact Sheet'!$B$8*'Fact Sheet'!$G$17)+($E$3*'Fact Sheet'!$B$8*'Fact Sheet'!$G$18)+($E$2*'Fact Sheet'!$B$8*'Fact Sheet'!$G$19) -> 42701.907 | F42: =($F$4*'Fact Sheet'!$B$8*'Fact Sheet'!$G$18)+($F$3*'Fact Sheet'!$B$8*'Fact Sheet'!$G$19) -> 27000 | G42: =$G$4*'Fact Sheet'!$B$8*'Fact Sheet'!$G$19 -> 0 | H42: 0 | I42: =$I$5*'Fact Sheet'!$B$8*'Fact Sheet'!$G$17 -> 23694.73 | J42: =($J$6*'Fact Sheet'!$B$8*'Fact Sheet'!$G$17)+($J$5*'Fact Sheet'!$B$8*'Fact Sheet'!$G$18) -> 29261.806 | K42: =($K$6*'Fact Sheet'!$B$8*'Fact Sheet'!$G$18)+($K$5*'Fact Sheet'!$B$8*'Fact Sheet'!$G$19) -> 29570.074 | L42: =$L$6*'Fact Sheet'!$B$8*'Fact Sheet'!$G$19 -> 9275.4199 | M42: 0 | N42: =SUM(B42:M42) -> 228907.75 | S42: Total Fixed Cost | T42: =$T$17/11 -> 137030 | U42: =$T$17/11 -> 137030 | V42: =$T$17/11 -> 137030 | W42: =$T$17/11 -> 137030 | X42: =$T$17/11 -> 137030 | Y42: =$T$17/11 -> 137030 | Z42: =$T$17/11 -> 137030 | AA42: =$T$17/11 -> 137030 | ... AD42: =$T$17/11 -> 137030 | AE42: 0 | AF42: =SUM(T42:AE42) -> 1507330
A43: Cucumbers | B43: 0 | C43: 0 | D43: 0 | E43: 0 | F43: =$F$7*'Fact Sheet'!$B$8*'Fact Sheet'!$H$17 -> 26250 | G43: =($G$8*'Fact Sheet'!$B$8*'Fact Sheet'!$H$17)+($G$7*'Fact Sheet'!$B$8*'Fact Sheet'!$H$18) -> 30000 | H43: =($H$9*'Fact Sheet'!$B$8*'Fact Sheet'!$H$17)+($H$8*'Fact Sheet'!$B$8*'Fact Sheet'!$H$18)+($H$7*'Fact Sheet'!$B$8*'Fact Sheet'!$H$19) -> 39909.446 | I43: =($I$9*'Fact Sheet'!$B$8*'Fact Sheet'!$H$18)+($I$8*'Fact Sheet'!$B$8*'Fact Sheet'!$H$19) -> 14808.492 | J43: =$J$9*'Fact Sheet'!$B$8*'Fact Sheet'!$H$19 -> 10675.477 | K43: 0 | L43: 0 | M43: 0 | N43: =SUM(B43:M43) -> 121643.42 | S43: Total Variable Cost | T43: =T38 -> 325740 | U43: =U38 -> 19365.228 | V43: =V38 -> 31842.487 | W43: =W38 -> 81127.452 | X43: =X38 -> 97998.056 | Y43: =Y38 -> 92855.536 | Z43: =Z38 -> 188557.37 | AA43: =AA38 -> 130895.58 | ... AE43: =AE38 -> 0 | AF43: =SUM(T43:AE43) -> 1365116.1
A44: Sweet Corn | B44: 0 | C44: 0 | D44: 0 | E44: 0 | F44: =$F$10*'Fact Sheet'!$B$8*'Fact Sheet'!$I$17 -> 0 | G44: =($G$11*'Fact Sheet'!$B$8*'Fact Sheet'!$I$17)+($G$10*'Fact Sheet'!$B$8*'Fact Sheet'!$I$18) -> 14233.969 | H44: =($H$11*'Fact Sheet'!$B$8*'Fact Sheet'!$I$18)+($H$10*'Fact Sheet'!$B$8*'Fact Sheet'!$I$18) -> 10675.477 | I44: =($I$11*'Fact Sheet'!$B$8*'Fact Sheet'!$I$18)+($I$10*'Fact Sheet'!$B$8*'Fact Sheet'!$I$19) -> 10675.477 | J44: =$J$11*'Fact Sheet'!$B$8*'Fact Sheet'!$I$19 -> 12454.723 | K44: 0 | L44: 0 | M44: 0 | N44: =SUM(B44:M44) -> 48039.646 | S44: Total Cost | T44: =SUM(T42:T43) -> 462770 | U44: =SUM(U42:U43) -> 156395.23 | V44: =SUM(V42:V43) -> 168872.49 | W44: =SUM(W42:W43) -> 218157.45 | X44: =SUM(X42:X43) -> 235028.06 | Y44: =SUM(Y42:Y43) -> 229885.54 | Z44: =SUM(Z42:Z43) -> 325587.37 | AA44: =SUM(AA42:AA43) -> 267925.58 | ... AE44: =SUM(AE42:AE43) -> 0 | AF44: =SUM(T44:AE44) -> 2872446.1 | AG44: <= | AH44: ='Fact Sheet'!$B$13 -> 3000000
A45: Napa Cabbage | B45: 0 | C45: 0 | D45: =$D$12*'Fact Sheet'!$B$8*'Fact Sheet'!$J$17 -> 28467.938 | E45: =$E$12*'Fact Sheet'!$B$8*'Fact Sheet'!$J$18 -> 14233.969 | F45: =$F$12*'Fact Sheet'!$B$8*'Fact Sheet'!$J$18 -> 14233.969 | G45: =$G$12*'Fact Sheet'!$B$8*'Fact Sheet'!$J$19 -> 17792.461 | H45: 0 | I45: =$I$13*'Fact Sheet'!$B$8*'Fact Sheet'!$J$17 -> 35469.562 | J45: =$J$13*'Fact Sheet'!$B$8*'Fact Sheet'!$J$18 -> 17734.781 | K45: =$K$13*'Fact Sheet'!$B$8*'Fact Sheet'!$J$18 -> 17734.781 | L45: =$L$13*'Fact Sheet'!$B$8*'Fact Sheet'!$J$19 -> 22168.476 | M45: 0 | N45: =SUM(B45:M45) -> 167835.94
A46: Hot Peppers | B46: 0 | C46: 0 | D46: 0 | E46: =$E$14*'Fact Sheet'!$B$8*'Fact Sheet'!$K$17 -> 63064.123 | F46: =$F$14*'Fact Sheet'!$B$8*'Fact Sheet'!$K$18 -> 39415.077 | G46: =$G$14*'Fact Sheet'!$B$8*'Fact Sheet'!$K$18 -> 39415.077 | H46: =$H$14*'Fact Sheet'!$B$8*'Fact Sheet'!$K$18 -> 39415.077 | I46: =$I$14*'Fact Sheet'!$B$8*'Fact Sheet'!$K$19 -> 19707.539 | J46: =$J$14*'Fact Sheet'!$B$8*'Fact Sheet'!$K$19 -> 19707.539 | K46: =$K$14*'Fact Sheet'!$B$8*'Fact Sheet'!$K$19 -> 19707.539 | L46: 0 | M46: 0 | N46: =SUM(B46:M46) -> 240431.97
...

Sheet Fact Sheet
A1: Month-specific Constraint
A2: Type | B2: JAN | C2: FEB | D2: MAR | E2: APR | F2: MAY | G2: JUN | H2: JUL | I2: AUG | J2: SEP | K2: OCT | L2: NOV | M2: DEC | N2: Units | O2: Editable?
A3: Available Water (catchment potential) | B3: 90000 | C3: 90000 | D3: 157500 | E3: 180000 | F3: 225000 | G3: 225000 | H3: 225000 | I3: 225000 | J3: 202500 | K3: 157500 | L3: 112500 | M3: 90000 | N3: Liter | O3: Yes
A4: Available Seasonal Labor | B4: 1280 | C4: 1280 | D4: 1280 | E4: 3840 | F4: 3840 | G4: 3840 | H4: 7680 | I4: 7680 | J4: 7680 | K4: 7680 | L4: 3840 | M4: 1280 | N4: hours | O4: Yes
A6: Generic Information | F6: Crop-specific Information
A7: Type | B7: Value | C7: Units | D7: Editable? | F7: Type | G7: Spinach | H7: Cucumbers | I7: Sweet Corn | J7: Napa Cabbage | K7: Hot Peppers | L7: Garlic | M7: Units | N7: Editable?
A8: Total Available Land | B8: 150 | C8: Acre | D8: Yes | F8: Seed Required | G8: 10 | H8: 2.5 | I8: 12 | J8: 0.75 | K8: 0.35 | L8: 1000 | M8: Pounds / Acre / Month | N8: No
A9: Total Available Harvest & Seed Storage | B9: 24000 | C9: Cubic Meter | D9: Yes | F9: Yield | G9: 13000 | H9: 16000 | I9: 10000 | J9: 45000 | K9: 5000 | L9: 11000 | M9: Pounds / Acre / Month | N9: Yes
A10: Total Available Water Storage | B10: 15000 | C10: Liter | D10: Yes | F10: Crop Size | G10: 0.075 | H10: 0.015 | I10: 0.015 | J10: 0.02 | K10: 0.035 | L10: 0.025 | M10: Cubic Meter / Pound | N10: Yes
A11: Equipment & General Storage | B11: 30000 | C11: Cubic Meter | D11: Yes | F11: Seed to Harvest Time Required
A12: Fuel Storage | B12: 750 | C12: Liter | D12: Yes | F12: - Planting | G12: 1 | H12: 1 | I12: 1 | J12: 1 | K12: 1 | L12: 1 | M12: Months / Crop Phase | N12: No
A13: Total Available Budget | B13: 3000000 | C13: US$ / Year | D13: Yes | F13: - Growing | G13: 1 | H13: 1 | I13: 2 | J13: 2 | K13: 3 | L13: 5 | M13: Months / Crop Phase | N13: No
F14: - Harvesting | G14: 1 | H14: 1 | I14: 1 | J14: 1 | K14: 3 | L14: 1 | M14: Months / Crop Phase | N14: No
A15: Fixed Cost Information | F15: Total Seed to Harvest Time Required | G15: =SUM(G12:G14) -> 3 | H15: =SUM(H12:H14) -> 3 | I15: =SUM(I12:I14) -> 4 | J15: =SUM(J12:J14) -> 4 | K15: =SUM(K12:K14) -> 7 | L15: =SUM(L12:L14) -> 7 | M15: Months | N15: No
A16: Type | B16: Cost | C16: Units | D16: Editable? | F16: Water Required
A17: Harvest & Seed Storage | B17: 2 | C17: US$ / Cubic Meter / Month | D17: Yes | F17: - Planting | G17: 1250 | H17: 1750 | I17: 1000 | J17: 2000 | K17: 2000 | L17: 1500 | M17: Liter / Crop Phase / Acre / Month | N17: Yes
A18: Water Storage | B18: 0.002 | C18: US$ / Liter / Month | D18: Yes | F18: - Growing | G18: 1000 | H18: 250 | I18: 750 | J18: 1000 | K18: 1250 | L18: 500 | M18: Liter / Crop Phase / Acre / Month | N18: Yes
A19: Irrigation System | B19: 175 | C19: US$ / Acre / Month | D19: Yes | F19: - Harvesting | G19: 1125 | H19: 750 | I19: 875 | J19: 1250 | K19: 625 | L19: 1000 | M19: Liter / Crop Phase / Acre / Month | N19: Yes
A20: Equipment & General Storage | B20: 2 | C20: US$ / Cubic Meter / Month | D20: Yes | F20: Total Water Required | G20: =SUM(G17:G19) -> 3375 | H20: =SUM(H17:H19) -> 2750 | I20: =SUM(I17:I19) -> 2625 | J20: =SUM(J17:J19) -> 4250 | K20: =SUM(K17:K19) -> 3875 | L20: =SUM(L17:L19) -> 3000 | M20: Liter / Acre / Month | N20: No
A21: Fuel Storage | B21: 0.2 | C21: US$ / Liter / Month | D21: Yes | F21: Fertilizer & Pesticide Required
A22: Machinery | B22: 2600 | C22: US$ / Month | D22: Yes | F22: - Planting | G22: 15 | H22: 12 | I22: 20 | J22: 15 | K22: 10 | L22: 8 | M22: Pounds / Crop Phase / Acre / Month | N22: Yes
F23: - Growing | G23: 10 | H23: 8 | I23: 15 | J23: 10 | K23: 12 | L23: 5 | M23: Pounds / Crop Phase / Acre / Month | N23: Yes
A24: Variable Cost Information | F24: - Harvesting | G24: 5 | H24: 5 | I24: 8 | J24: 5 | K24: 6 | L24: 3 | M24: Pounds / Crop Phase / Acre / Month | N24: Yes
A25: Type | B25: Cost | C25: Units | D25: Editable? | F25: Total Fertilizer & Pesticide Required | G25: =SUM(G22:G24) -> 30 | H25: =SUM(H22:H24) -> 25 | I25: =SUM(I22:I24) -> 43 | J25: =SUM(J22:J24) -> 30 | K25: =SUM(K22:K24) -> 28 | L25: =SUM(L22:L24) -> 16 | M25: Pounds / Acre / Month | N25: No
A26: Fertilizer & Pesticide | B26: 2 | C26: US$ / Pound | D26: Yes | F26: Crop Diversity | G26: 0.8 | H26: 0.3 | I26: 0.3 | J26: 0.5 | K26: 0.3 | L26: 0.5 | M26: Percentage | N26: Yes
A27: Seasonal Labor | B27: 20 | C27: US$ / hour | D27: Yes
A28: Fuel | B28: 1 | C28: US$ / Liter | D28: Yes | F28: Crop-specific Revenue-related Information
A29: Water Supply | B29: 0.002 | C29: US$ / Liter | D29: Yes | F29: Type | G29: Spinach | H29: Cucumbers | I29: Sweet Corn | J29: Napa Cabbage | K29: Hot Peppers | L29: Garlic | M29: Units | N29: Editable?
F30: Demand
F31: - Wholesale Distributer | G31: 45000 | H31: 42187.5 | I31: 10000 | J31: 67500 | K31: 36562.5 | L31: 84375 | M31: Pounds / Marketing Channel / Month | N31: Yes
F32: - D2C (Digital / Farmer's Market) | G32: 14062.5 | H32: 16875 | I32: 25000 | J32: 28125 | K32: 7031.25 | L32: 8437.5 | M32: Pounds / Marketing Channel / Month | N32: Yes
F33: - B2B (Restaurants, etc.) | G33: 21093.75 | H33: 22500 | I33: 15000 | J33: 35156.25 | K33: 14062.5 | L33: 10125 | M33: Pounds / Marketing Channel / Month | N33: Yes
F34: Total Demand (monthly) | G34: =SUM(G31:G33) -> 80156.25 | H34: =SUM(H31:H33) -> 81562.5 | I34: =SUM(I31:I33) -> 50000 | J34: =SUM(J31:J33) -> 130781.25 | K34: =SUM(K31:K33) -> 57656.25 | L34: =SUM(L31:L33) -> 102937.5 | M34: Pounds / Month | N34: No
F35: Price
F36: - Wholesale Distributer | G36: 2.5 | H36: 1.25 | I36: 1 | J36: 0.5 | K36: 1.5 | L36: 2.25 | M36: US$ / Pound / Marketing Channel | N36: Yes
F37: - D2C (Digital / Farmer's Market) | G37: 6.5 | H37: 2.75 | I37: 3.25 | J37: 1.25 | K37: 8 | L37: 8 | M37: US$ / Pound / Marketing Channel | N37: Yes
F38: - B2B (Restaurants, etc.) | G38: 3.5 | H38: 1.5 | I38: 1.5 | J38: 0.75 | K38: 3 | L38: 3.75 | M38: US$ / Pound / Marketing Channel | N38: Yes
F39: Weighed Average Price | G39: =($G36*$G31/$G34)+($G37*$G32/$G34)+($G38*$G33/$G34) -> 3.4649123 | H39: =($H36*$H31/$H34)+($H37*$H32/$H34)+($H38*$H33/$H34) -> 1.6293103 | I39: =($I36*$I31/$I34)+($I37*$I32/$I34)+($I38*$I33/$I34) -> 2.275 | J39: =($J36*$J31/$J34)+($J37*$J32/$J34)+($J38*$J33/$J34) -> 0.72849462 | K39: =($K36*$K31/$K34)+($K37*$K32/$K34)+($K38*$K33/$K34) -> 2.6585366 | L39: =($L36*$L31/$L34)+($L37*$L32/$L34)+($L38*$L33/$L34) -> 2.8688525 | M39: US$ / Pound | N39: No
F41: Crop-specific Variable Cost Information
F42: Type | G42: Spinach | H42: Cucumbers | I42: Sweet Corn | J42: Napa Cabbage | K42: Hot Peppers | L42: Garlic | M42: Units | N42: Editable?
...

Sheet Appendix 1
A1: Crop Planting Calendar | B1: Jan | C1: Feb | D1: Mar | E1: Apr | F1: May | G1: June | H1: July | I1: Aug | J1: Sept | K1: Oct | L1: Nov | M1: Dec | N1: Plant | O1: Crop Diversity | T1: Model Summary
N2: (Y/N)
A3: Spinach #1 | C3: 0.15 | D3: 0.15 | E3: 0.15 | N3: 1 | O3: 0.15 | P3: <= | Q3: 0.16
A4: Spinach #2 | D4: 0.15 | E4: 0.15 | F4: 0.15 | N4: 1 | O4: 0.15 | P4: <= | Q4: 0.16
A5: Spinach #3 | E5: 0.15 | F5: 0.15 | G5: 0.15 | N5: 1 | O5: 0.15 | P5: <= | Q5: 0.16
A6: Spinach #4 | I6: 0.15 | J6: 0.15 | K6: 0.15 | N6: 1 | O6: 0.15 | P6: <= | Q6: 0.16
A7: Spinach #5 | J7: 0.15 | K7: 0.15 | L7: 0.15 | N7: 1 | O7: 0.15 | P7: <= | Q7: 0.16
A8: Cucumbers #1 | F8: 0.12 | G8: 0.12 | H8: 0.12 | N8: 1 | O8: 0.12 | P8: <= | Q8: 0.17
A9: Cucumbers #2 | G9: 0.12 | H9: 0.12 | I9: 0.12 | N9: 1 | O9: 0.12 | P9: <= | Q9: 0.17
A10: Cucumbers #3 | H10: 0.12 | I10: 0.12 | J10: 0.12 | N10: 1 | O10: 0.12 | P10: <= | Q10: 0.17 | T10: Jan | U10: Feb | V10: Mar | W10: Apr | X10: May | Y10: June | Z10: July | AA10: Aug | AB10: Sept | AC10: Oct | AD10: Nov | AE10: Dec
A11: Sweet Corn #1 | G11: - | H11: - | I11: - | N11: - | O11: - | P11: <= | Q11: - | S11: Spinach | T11: - | U11: 329 | V11: 592 | W11: 2784 | X11: 2455 | Y11: 2192 | Z11: - | AA11: 329 | AB11: 592 | AC11: 2455 | AD11: 2192 | AE11: -
A12: Sweet Corn #2 | H12: - | I12: - | J12: - | N12: - | O12: - | P12: <= | Q12: - | S12: Cucumbers | T12: - | U12: - | V12: - | W12: - | X12: 272 | Y12: 489 | Z12: 2846 | AA12: 2574 | AB12: 2356 | AC12: - | AD12: - | AE12: -
A13: Napa Cabbage #1 | E13: - | F13: - | G13: - | N13: - | O13: - | P13: <= | Q13: - | S13: Sweet Corn | T13: - | U13: - | V13: - | W13: - | X13: - | Y13: - | Z13: - | AA13: - | AB13: - | AC13: - | AD13: - | AE13: -
A14: Napa Cabbage #2 | J14: - | K14: - | L14: - | N14: - | O14: - | P14: <= | Q14: - | S14: Napa Cabbage | T14: - | U14: - | V14: - | W14: - | X14: - | Y14: - | Z14: - | AA14: - | AB14: - | AC14: - | AD14: - | AE14: -
A15: Hot Peppers #1 | F15: - | G15: - | H15: - | I15: - | J15: - | K15: - | N15: - | O15: - | P15: <= | Q15: - | S15: Hot Peppers | T15: - | U15: - | V15: - | W15: - | X15: - | Y15: - | Z15: - | AA15: - | AB15: - | AC15: - | AD15: - | AE15: -
A16: Garlic #1 | C16: - | D16: - | E16: - | F16: - | G16: - | H16: - | N16: - | O16: - | P16: <= | Q16: - | S16: Garlic | T16: - | U16: - | V16: - | W16: - | X16: - | Y16: - | Z16: - | AA16: - | AB16: - | AC16: - | AD16: - | AE16: -
B17: - | C17: 0.15 | D17: 0.29 | E17: 0.44 | F17: 0.41 | G17: 0.39 | H17: 0.36 | I17: 0.39 | J17: 0.41 | K17: 0.29 | L17: 0.15 | M17: - | N17: ^Binary^ Constraint | S17: Labor Constraints | T17: - | U17: 329 | V17: 592 | W17: 2784 | X17: 2727 | Y17: 2682 | Z17: 2846 | AA17: 2903 | AB17: 2948 | AC17: 2455 | AD17: 2192 | AE17: -
B18: <= | C18: <= | D18: <= | E18: <= | F18: <= | G18: <= | H18: <= | I18: <= | J18: <= | K18: <= | L18: <= | M18: <= | T18: <= | U18: <= | V18: <= | W18: <= | X18: <= | Y18: <= | Z18: <= | AA18: <= | AB18: <= | AC18: <= | AD18: <= | AE18: <=
B19: 1 | C19: 1 | D19: 1 | E19: 1 | F19: 1 | G19: 1 | H19: 1 | I19: 1 | J19: 1 | K19: 1 | L19: 1 | M19: 1 | T19: 1280 | U19: 1280 | V19: 1280 | W19: 3840 | X19: 3840 | Y19: 3840 | Z19: 7680 | AA19: 7680 | AB19: 7680 | AC19: 7680 | AD19: 3840 | AE19: 1280
A21: Water Supply Constraint | B21: Jan | C21: Feb | D21: Mar | E21: Apr | F21: May | G21: June | H21: July | I21: Aug | J21: Sept | K21: Oct | L21: Nov | M21: Dec | N21: IMAGE | S21: Harvest Storage | T21: Jan | U21: Feb | V21: Mar | W21: Apr | X21: May | Y21: June | Z21: July | AA21: Aug | AB21: Sept | AC21: Oct | AD21: Nov | AE21: Dec
A22: Spinach | B22: - | C22: 110 | D22: 197 | E22: 395 | F22: 285 | G22: 197 | H22: - | I22: 110 | J22: 197 | K22: 285 | L22: 197 | M22: - | T22: - | U22: - | V22: - | W22: 21375 | X22: 21375 | Y22: 21375 | Z22: - | AA22: - | AB22: - | AC22: 21375 | AD22: 21375 | AE22: -
A23: Cucumbers | B23: - | C23: - | D23: - | E23: - | F23: 127 | G23: 145 | H23: 254 | I23: 127 | J23: 109 | K23: - | L23: - | M23: - | T23: - | U23: - | V23: - | W23: - | X23: - | Y23: - | Z23: 4350 | AA23: 4350 | AB23: 4350 | AC23: - | AD23: - | AE23: -
A24: Sweet Corn | B24: - | C24: - | D24: - | E24: - | F24: - | G24: - | H24: - | I24: - | J24: - | K24: - | L24: - | M24: - | T24: - | U24: - | V24: - | W24: - | X24: - | Y24: - | Z24: - | AA24: - | AB24: - | AC24: - | AD24: - | AE24: -
A25: Napa Cabbage | B25: - | C25: - | D25: - | E25: - | F25: - | G25: - | H25: - | I25: - | J25: - | K25: - | L25: - | M25: - | T25: - | U25: - | V25: - | W25: - | X25: - | Y25: - | Z25: - | AA25: - | AB25: - | AC25: - | AD25: - | AE25: -
A26: Hot Peppers | B26: - | C26: - | D26: - | E26: - | F26: - | G26: - | H26: - | I26: - | J26: - | K26: - | L26: - | M26: - | T26: - | U26: - | V26: - | W26: - | X26: - | Y26: - | Z26: - | AA26: - | AB26: - | AC26: - | AD26: - | AE26: -
A27: Garlic | B27: - | C27: - | D27: - | E27: - | F27: - | G27: - | H27: - | I27: - | J27: - | K27: - | L27: - | M27: - | T27: - | U27: - | V27: - | W27: - | X27: - | Y27: - | Z27: - | AA27: - | AB27: - | AC27: - | AD27: - | AE27: -
B28: - | C28: 110 | D28: 197 | E28: 395 | F28: 412 | G28: 342 | H28: 254 | I28: 236 | J28: 306 | K28: 285 | L28: 197 | M28: - | T28: - | U28: - | V28: - | W28: 21375 | X28: 21375 | Y28: 21375 | Z28: 4350 | AA28: 4350 | AB28: 4350 | AC28: 21375 | AD28: 21375 | AE28: -
B29: <= | C29: <= | D29: <= | E29: <= | F29: <= | G29: <= | H29: <= | I29: <= | J29: <= | K29: <= | L29: <= | M29: <= | T29: <= | U29: <= | V29: <= | W29: <= | X29: <= | Y29: <= | Z29: <= | AA29: <= | AB29: <= | AC29: <= | AD29: <= | AE29: <=
B30: 750 | C30: 750 | D30: 750 | E30: 750 | F30: 750 | G30: 750 | H30: 750 | I30: 750 | J30: 750 | K30: 750 | L30: 750 | M30: 750 | T30: 24000 | U30: 24000 | V30: 24000 | W30: 24000 | X30: 24000 | Y30: 24000 | Z30: 24000 | AA30: 24000 | AB30: 24000 | AC30: 24000 | AD30: 24000 | AE30: 24000
A32: Channel Sales & Yield (lbs) | B32: Jan | C32: Feb | D32: Mar | E32: Apr | F32: May | G32: June | H32: July | I32: Aug | J32: Sept | K32: Oct | L32: Nov | M32: Dec | N32: Demand Cap | S32: Total Sales (lbs) | T32: UCM (lb/ Channel/Crop) | U32: Contributions (Channel/Crop) | V32: Succession Fixed Costs (by Crop) | W32: Total Variable Costs | X32: Total Fixed Costs | Y32: Total Costs | AD32: 0
N33: (Lbs/Mo)
A34: Spinach (Harvest) | B34: 0 | C34: 0 | D34: 0 | E34: 285000 | F34: 285000 | G34: 285000 | H34: 0 | I34: 0 | J34: 0 | K34: 285000 | L34: 285000 | M34: 0 | N34: = | O34: 1425000 | W34: 3411697.7 | X34: 664980 | Y34: 4076677.7
A35: <= | B35: 0 | C35: 0 | D35: 0 | E35: 285000 | F35: 285000 | G35: 285000 | H35: 0 | I35: 0 | J35: 0 | K35: 285000 | L35: 285000 | M35: 0
A36: Wholesale | B36: 0 | C36: 0 | D36: 0 | E36: 160000 | F36: 160000 | G36: 160000 | H36: 0 | I36: 0 | J36: 0 | K36: 160000 | L36: 160000 | M36: 0 | N36: <= | O36: 160000 | S36: 800000 | T36: 1.02 | U36: 813452.31 | V36: 24000 | Y36: <=
A37: D2C | B37: 0 | C37: 0 | D37: 0 | E37: 50000 | F37: 50000 | G37: 50000 | H37: 0 | I37: 0 | J37: 0 | K37: 50000 | L37: 50000 | M37: 0 | N37: <= | O37: 50000 | S37: 250000 | T37: 6.52 | U37: 1629203.9 | Y37: 1500000
A38: B2B | B38: 0 | C38: 0 | D38: 0 | E38: 75000 | F38: 75000 | G38: 75000 | H38: 0 | I38: 0 | J38: 0 | K38: 75000 | L38: 75000 | M38: 0 | N38: <= | O38: 75000 | S38: 375000 | T38: 2.02 | U38: 756305.77
A39: Cucumbers (Harvest) | B39: 0 | C39: 0 | D39: 0 | E39: 0 | F39: 0 | G39: 0 | H39: 290000 | I39: 290000 | J39: 290000 | K39: 0 | L39: 0 | M39: 0 | N39: = | O39: 870000
B40: 0 | C40: 0 | D40: 0 | E40: 0 | F40: 0 | G40: 0 | H40: 290000 | I40: 290000 | J40: 290000 | K40: 0 | L40: 0 | M40: 0
A41: Wholesale | B41: 0 | C41: 0 | D41: 0 | E41: 0 | F41: 0 | G41: 0 | H41: 150000 | I41: 150000 | J41: 150000 | K41: 0 | L41: 0 | M41: 0 | N41: <= | O41: 150000 | S41: 450000 | T41: 0.01 | U41: 3538.13 | V41: 9900
A42: D2C | B42: 0 | C42: 0 | D42: 0 | E42: 0 | F42: 0 | G42: 0 | H42: 60000 | I42: 60000 | J42: 60000 | K42: 0 | L42: 0 | M42: 0 | N42: <= | O42: 60000 | S42: 180000 | T42: 2.51 | U42: 451415.25
...

Sheet Appendix 2
A1: Type of Crop | B1: Marketing Channel | C1: Grade | D1: Demand | E1: Price | G1: Sorted Marketing Channel | H1: Sorted Grade | I1: Sorted Demand | J1: Sorted Price | L1: Annual Yield / Year | M1: Sales / Sales Channel / Year | N1: Revenue / Sales Channel / Year
A2: Spinach | B2: Wholesale Distributer | C2: Normal | D2: 100000 | E2: 1 | G2: {=_xlfn._xlws.SORT(B2:E7,4,-1,FALSE)} -> B2B (Restaurants, etc.) | H2: Premium | I2: 5000 | J2: 3.6 | L2: 110000 | M2: =IF($L2>=$I2,$I2,L2) -> 5000 | N2: =J2*M2 -> 18000
A3: Spinach | B3: D2C (Digital / Farmer's Market) | C3: Normal | D3: 17500 | E3: 2 | G3: B2B (Restaurants, etc.) | H3: Normal | I3: 25000 | J3: 3 | M3: =IF(L2-M2>=I3,I3,L2-M2) -> 25000 | N3: =J3*M3 -> 75000
A4: Spinach | B4: B2B (Restaurants, etc.) | C4: Normal | D4: 25000 | E4: 3 | G4: D2C (Digital / Farmer's Market) | H4: Premium | I4: 3500 | J4: 2.4 | M4: =IF(L2-M2-M3>=I4,I4,L2-M2-M3) -> 3500 | N4: =J4*M4 -> 8400
A5: Spinach | B5: Wholesale Distributer | C5: Premium | D5: =0.2*D2 -> 20000 | E5: =1.2*E2 -> 1.2 | G5: D2C (Digital / Farmer's Market) | H5: Normal | I5: 17500 | J5: 2 | M5: =IF(L2-M2-M3-M4>=I5,I5,L2-M2-M3-M4) -> 17500 | N5: =J5*M5 -> 35000
A6: Spinach | B6: D2C (Digital / Farmer's Market) | C6: Premium | D6: =0.2*D3 -> 3500 | E6: =1.2*E3 -> 2.4 | G6: Wholesale Distributer | H6: Premium | I6: 20000 | J6: 1.2 | M6: =IF(L2-M2-M3-M4-M5>=I6,I6,L2-M2-M3-M4-M5) -> 20000 | N6: =J6*M6 -> 24000
A7: Spinach | B7: B2B (Restaurants, etc.) | C7: Premium | D7: =0.2*D4 -> 5000 | E7: =1.2*E4 -> 3.6 | G7: Wholesale Distributer | H7: Normal | I7: 100000 | J7: 1 | M7: =IF(L2-M2-M3-M4-M5-M6>=I7,I7,L2-M2-M3-M4-M5-M6) -> 39000 | N7: =J7*M7 -> 39000
A8: Cucumbers | B8: Wholesale Distributer | C8: Normal | D8: 150000 | E8: 1 | G8: {=_xlfn._xlws.SORT(B8:E13,4,-1,FALSE)} -> B2B (Restaurants, etc.) | H8: Premium | I8: 5600 | J8: 3.6 | L8: 120000 | M8: =IF(L8>=I8,I8,L8) -> 5600 | N8: =J8*M8 -> 20160
A9: Cucumbers | B9: D2C (Digital / Farmer's Market) | C9: Normal | D9: 20000 | E9: 2 | G9: B2B (Restaurants, etc.) | H9: Normal | I9: 28000 | J9: 3 | M9: =IF(L8-M8>=I9,I9,L8-M8) -> 28000 | N9: =J9*M9 -> 84000
A10: Cucumbers | B10: B2B (Restaurants, etc.) | C10: Normal | D10: 28000 | E10: 3 | G10: D2C (Digital / Farmer's Market) | H10: Premium | I10: 4000 | J10: 2.4 | M10: =IF(L8-M8-M9>=I10,I10,L8-M8-M9) -> 4000 | N10: =J10*M10 -> 9600
A11: Cucumbers | B11: Wholesale Distributer | C11: Premium | D11: =0.2*D8 -> 30000 | E11: =1.2*E8 -> 1.2 | G11: D2C (Digital / Farmer's Market) | H11: Normal | I11: 20000 | J11: 2 | M11: =IF(L8-M8-M9-M10>=I11,I11,L8-M8-M9-M10) -> 20000 | N11: =J11*M11 -> 40000
A12: Cucumbers | B12: D2C (Digital / Farmer's Market) | C12: Premium | D12: =0.2*D9 -> 4000 | E12: =1.2*E9 -> 2.4 | G12: Wholesale Distributer | H12: Premium | I12: 30000 | J12: 1.2 | M12: =IF(L8-M8-M9-M10-M11>=I12,I12,L8-M8-M9-M10-M11) -> 30000 | N12: =J12*M12 -> 36000
A13: Cucumbers | B13: B2B (Restaurants, etc.) | C13: Premium | D13: =0.2*D10 -> 5600 | E13: =1.2*E10 -> 3.6 | G13: Wholesale Distributer | H13: Normal | I13: 150000 | J13: 1 | M13: =IF(L8-M8-M9-M10-M11-M12>=I13,I13,L8-M8-M9-M10-M11-M12) -> 32400 | N13: =J13*M13 -> 32400
A14: Sweet Corn | B14: Wholesale Distributer | C14: Normal | D14: 175000 | E14: 4 | G14: {=_xlfn._xlws.SORT(B14:E19,4,-1,FALSE)} -> B2B (Restaurants, etc.) | H14: Premium | I14: 10000 | J14: 7.2 | L14: 130000 | M14: =IF(L14>=I14,I14,L14) -> 10000 | N14: =J14*M14 -> 72000
A15: Sweet Corn | B15: D2C (Digital / Farmer's Market) | C15: Normal | D15: 22500 | E15: 5 | G15: B2B (Restaurants, etc.) | H15: Normal | I15: 50000 | J15: 6 | M15: =IF(L14-M14>=I15,I15,L14-M14) -> 50000 | N15: =J15*M15 -> 300000
A16: Sweet Corn | B16: B2B (Restaurants, etc.) | C16: Normal | D16: 50000 | E16: 6 | G16: D2C (Digital / Farmer's Market) | H16: Premium | I16: 4500 | J16: 6 | M16: =IF(L14-M14-M15>=I16,I16,L14-M14-M15) -> 4500 | N16: =J16*M16 -> 27000
A17: Sweet Corn | B17: Wholesale Distributer | C17: Premium | D17: =0.2*D14 -> 35000 | E17: =1.2*E14 -> 4.8 | G17: D2C (Digital / Farmer's Market) | H17: Normal | I17: 22500 | J17: 5 | M17: =IF(L14-M14-M15-M16>=I17,I17,L14-M14-M15-M16) -> 22500 | N17: =J17*M17 -> 112500
A18: Sweet Corn | B18: D2C (Digital / Farmer's Market) | C18: Premium | D18: =0.2*D15 -> 4500 | E18: =1.2*E15 -> 6 | G18: Wholesale Distributer | H18: Premium | I18: 35000 | J18: 4.8 | M18: =IF(L14-M14-M15-M16-M17>=I18,I18,L14-M14-M15-M16-M17) -> 35000 | N18: =J18*M18 -> 168000
A19: Sweet Corn | B19: B2B (Restaurants, etc.) | C19: Premium | D19: =0.2*D16 -> 10000 | E19: =1.2*E16 -> 7.2 | G19: Wholesale Distributer | H19: Normal | I19: 175000 | J19: 4 | M19: =IF(L14-M14-M15-M16-M17-M18>=I19,I19,L14-M14-M15-M16-M17-M18) -> 8000 | N19: =J19*M19 -> 32000
A20: Napa Cabbage | B20: Wholesale Distributer | C20: Normal | D20: 225000 | E20: 4 | G20: {=_xlfn._xlws.SORT(B20:E25,4,-1,FALSE)} -> B2B (Restaurants, etc.) | H20: Premium | I20: 12000 | J20: 7.2 | L20: 140000 | M20: =IF(L20>=I20,I20,L20) -> 12000 | N20: =J20*M20 -> 86400
A21: Napa Cabbage | B21: D2C (Digital / Farmer's Market) | C21: Normal | D21: 15000 | E21: 5 | G21: B2B (Restaurants, etc.) | H21: Normal | I21: 60000 | J21: 6 | M21: =IF(L20-M20>=I21,I21,L20-M20) -> 60000 | N21: =J21*M21 -> 360000
A22: Napa Cabbage | B22: B2B (Restaurants, etc.) | C22: Normal | D22: 60000 | E22: 6 | G22: D2C (Digital / Farmer's Market) | H22: Premium | I22: 3000 | J22: 6 | M22: =IF(L20-M20-M21>=I22,I22,L20-M20-M21) -> 3000 | N22: =J22*M22 -> 18000
A23: Napa Cabbage | B23: Wholesale Distributer | C23: Premium | D23: =0.2*D20 -> 45000 | E23: =1.2*E20 -> 4.8 | G23: D2C (Digital / Farmer's Market) | H23: Normal | I23: 15000 | J23: 5 | M23: =IF(L20-M20-M21-M22>=I23,I23,L20-M20-M21-M22) -> 15000 | N23: =J23*M23 -> 75000
A24: Napa Cabbage | B24: D2C (Digital / Farmer's Market) | C24: Premium | D24: =0.2*D21 -> 3000 | E24: =1.2*E21 -> 6 | G24: Wholesale Distributer | H24: Premium | I24: 45000 | J24: 4.8 | M24: =IF(L20-M20-M21-M22-M23>=I24,I24,L20-M20-M21-M22-M23) -> 45000 | N24: =J24*M24 -> 216000
A25: Napa Cabbage | B25: B2B (Restaurants, etc.) | C25: Premium | D25: =0.2*D22 -> 12000 | E25: =1.2*E22 -> 7.2 | G25: Wholesale Distributer | H25: Normal | I25: 225000 | J25: 4 | M25: =IF(L20-M20-M21-M22-M23-M24>=I25,I25,L20-M20-M21-M22-M23-M24) -> 5000 | N25: =J25*M25 -> 20000
A26: Hot Peppers | B26: Wholesale Distributer | C26: Normal | D26: 100000 | E26: 7 | G26: {=_xlfn._xlws.SORT(B26:E31,4,-1,FALSE)} -> B2B (Restaurants, etc.) | H26: Premium | I26: 3600 | J26: 10.8 | L26: 150000 | M26: =IF(L26>=I26,I26,L26) -> 3600 | N26: =J26*M26 -> 38880
A27: Hot Peppers | B27: D2C (Digital / Farmer's Market) | C27: Normal | D27: 7000 | E27: 8 | G27: D2C (Digital / Farmer's Market) | H27: Premium | I27: 1400 | J27: 9.6 | M27: =IF(L26-M26>=I27,I27,L26-M26) -> 1400 | N27: =J27*M27 -> 13440
A28: Hot Peppers | B28: B2B (Restaurants, etc.) | C28: Normal | D28: 18000 | E28: 9 | G28: B2B (Restaurants, etc.) | H28: Normal | I28: 18000 | J28: 9 | M28: =IF(L26-M26-M27>=I28,I28,L26-M26-M27) -> 18000 | N28: =J28*M28 -> 162000
A29: Hot Peppers | B29: Wholesale Distributer | C29: Premium | D29: =0.2*D26 -> 20000 | E29: =1.2*E26 -> 8.4 | G29: Wholesale Distributer | H29: Premium | I29: 20000 | J29: 8.4 | M29: =IF(L26-M26-M27-M28>=I29,I29,L26-M26-M27-M28) -> 20000 | N29: =J29*M29 -> 168000
A30: Hot Peppers | B30: D2C (Digital / Farmer's Market) | C30: Premium | D30: =0.2*D27 -> 1400 | E30: =1.2*E27 -> 9.6 | G30: D2C (Digital / Farmer's Market) | H30: Normal | I30: 7000 | J30: 8 | M30: =IF(L26-M26-M27-M28-M29>=I30,I30,L26-M26-M27-M28-M29) -> 7000 | N30: =J30*M30 -> 56000
A31: Hot Peppers | B31: B2B (Restaurants, etc.) | C31: Premium | D31: =0.2*D28 -> 3600 | E31: =1.2*E28 -> 10.8 | G31: Wholesale Distributer | H31: Normal | I31: 100000 | J31: 7 | M31: =IF(L26-M26-M27-M28-M29-M30>=I31,I31,L26-M26-M27-M28-M29-M30) -> 100000 | N31: =J31*M31 -> 700000
A32: Garlic | B32: Wholesale Distributer | C32: Normal | D32: 225000 | E32: 7 | G32: {=_xlfn._xlws.SORT(B32:E37,4,-1,FALSE)} -> B2B (Restaurants, etc.) | H32: Premium | I32: 3600 | J32: 10.8 | L32: 280000 | M32: =IF(L32>=I32,I32,L32) -> 3600 | N32: =J32*M32 -> 38880
A33: Garlic | B33: D2C (Digital / Farmer's Market) | C33: Normal | D33: 15000 | E33: 8 | G33: D2C (Digital / Farmer's Market) | H33: Premium | I33: 3000 | J33: 9.6 | M33: =IF(L32-M32>=I33,I33,L32-M32) -> 3000 | N33: =J33*M33 -> 28800
A34: Garlic | B34: B2B (Restaurants, etc.) | C34: Normal | D34: 18000 | E34: 9 | G34: B2B (Restaurants, etc.) | H34: Normal | I34: 18000 | J34: 9 | M34: =IF(L32-M32-M33>=I34,I34,L32-M32-M33) -> 18000 | N34: =J34*M34 -> 162000
A35: Garlic | B35: Wholesale Distributer | C35: Premium | D35: =0.2*D32 -> 45000 | E35: =1.2*E32 -> 8.4 | G35: Wholesale Distributer | H35: Premium | I35: 45000 | J35: 8.4 | M35: =IF(L32-M32-M33-M34>=I35,I35,L32-M32-M33-M34) -> 45000 | N35: =J35*M35 -> 378000
A36: Garlic | B36: D2C (Digital / Farmer's Market) | C36: Premium | D36: =0.2*D33 -> 3000 | E36: =1.2*E33 -> 9.6 | G36: D2C (Digital / Farmer's Market) | H36: Normal | I36: 15000 | J36: 8 | M36: =IF(L32-M32-M33-M34-M35>=I36,I36,L32-M32-M33-M34-M35) -> 15000 | N36: =J36*M36 -> 120000
A37: Garlic | B37: B2B (Restaurants, etc.) | C37: Premium | D37: =0.2*D34 -> 3600 | E37: =1.2*E34 -> 10.8 | G37: Wholesale Distributer | H37: Normal | I37: 225000 | J37: 7 | M37: =IF(L32-M32-M33-M34-M35-M36>=I37,I37,L32-M32-M33-M34-M35-M36) -> 195400 | N37: =J37*M37 -> 1367800
